Workbook

Sheet README
A1: PROJECT 1 — EQUITY RESEARCH & VALUATION
A2: Company | B2: Lucky Cement Limited (PSX: LUCK)
A3: Data period | B3: FY2022–FY2026 (five fiscal years)
A4: Currency | B4: PKR
A5: Financial statement unit | B5: PKR million unless stated otherwise
A6: Purpose | B6: Raw research dataset only. Excel modelling and Power BI shaping come next.
A7: Important | B7: Do not change source figures. Calculations, forecasts, DCF, ratios and valuation will be built separately.
A8: Primary source | B8: Lucky Cement official Financial Reports / Annual Reports
A9: Market source | B9: Pakistan Stock Exchange (PSX) and S&P Global Market Intelligence data surfaced by StockAnalysis
A10: Latest market snapshot | B10: 20-Aug-2026 close

Sheet Income Statement
A1: matric | B1: FY2022 | C1: FY2023 | D1: FY2024 | E1: FY2025 | F1: FY2026 | G1: Source
A2: Gross Revenue | B2: =402158.149/1000 -> 402.15815 | C2: 459.45916 | D2: 489.36345 | E2: 563.63445 | F2: 645.92833 | G2: Lucky Cement annual reports / FY2026 results; PKR million
A3: Sales tax & excise duty | B3: 58.345772 | C3: 63.863527 | D3: 64.681767 | E3: 94.691953 | F3: 108.6495 | G3: Lucky Cement annual reports / FY2026 results; PKR million
A4: Rebates / incentives / commission | B4: 12.350263 | C4: 10.470447 | D4: 13.686497 | E4: 14.882534 | F4: 20.920014 | G4: Lucky Cement annual reports / FY2026 results; PKR million
A5: Net Revenue | B5: 331.46211 | C5: 385.12519 | D5: 410.99518 | E5: 454.05997 | F5: 516.35881 | G5: Lucky Cement FY2022 annual report; FY2023–FY2025 reports; FY2026 results (FY2025 restated comparative)
A6: Cost of Sales | B6: 268.29062 | C6: 291.49119 | D6: 287.47824 | E6: 326.89205 | F6: 385.05378 | G6: Lucky Cement annual reports / FY2026 results; PKR million
A7: Gross Profit | B7: 63.171496 | C7: 93.634 | D7: 123.51694 | E7: 127.16791 | F7: 131.30503 | G7: Lucky Cement annual reports / FY2026 results; PKR million
A8: Distribution Cost | B8: 11.8247 | C8: 10.627616 | D8: 15.785581 | E8: 17.254021 | F8: 16.94106 | G8: Lucky Cement annual reports / FY2026 results; PKR million
A9: Administrative Expenses | B9: 5.760738 | C9: 6.711136 | D9: 7.652978 | E9: 7.559413 | F9: 8.58398 | G9: Lucky Cement annual reports / FY2026 results; PKR million
A10: Finance Cost | B10: 7.095208 | C10: 80.640895 | D10: 36.698507 | E10: 25.498349 | F10: 18.942526 | G10: Lucky Cement annual reports / FY2026 results; PKR million
A11: Other Expenses | B11: 4.465504 | C11: 4.126454 | D11: 3.674585 | E11: 4.728985 | F11: 8.006359 | G11: Lucky Cement annual reports / FY2026 results; PKR million
A12: Gain on Bargain Purchase | B12: 0 | C12: 0 | D12: 0 | E12: 0.292555 | F12: 0 | G12: Lucky Cement annual reports / FY2026 results; PKR million
A13: Other Income | B13: 7.33663 | C13: 9.27816 | D13: 16.18537 | E13: 15.890653 | F13: 20.972833 | G13: Lucky Cement annual reports / FY2026 results; PKR million
A14: Share of Profit - JV & Associates | B14: 5.674108 | C14: 10.521551 | D14: 16.209618 | E14: 17.779995 | F14: 16.753167 | G14: Lucky Cement annual reports / FY2026 results; PKR million
... A20: EPS Attributable to Owners (PKR) | B20: 18.24 | C20: 30.59 | D20: 44.1 | E20: 52.53 | F20: 60.78 | G20: Lucky Cement consolidated EPS

Sheet Balance Sheet
A1: metric | B1: FY2022 | C1: FY2023 | D1: FY2024 | E1: FY2025 | F1: FY2026 | G1: Source
A2: Cash & Equivalents | B2: 16.9 | C2: 38.939 | D2: 41.964 | E2: 61.685 | F2: 8.86 | G2: S&P Global Market Intelligence via StockAnalysis; PKR million except shares/BVPS
A3: Short-Term Investments | B3: 0.243 | C3: 0.713 | D3: 22.67 | E3: 0 | F3: 173.1 | G3: S&P Global Market Intelligence via StockAnalysis; PKR million except shares/BVPS
A4: Trading Asset Securities | B4: 12.733 | C4: 43.486 | D4: 44.876 | E4: 80.091 | F4: 0 | G4: S&P Global Market Intelligence via StockAnalysis; PKR million except shares/BVPS
A5: Cash & Short-Term Investments | B5: 29.877 | C5: 83.139 | D5: 86.863 | E5: 141.777 | F5: 181.961 | G5: S&P Global Market Intelligence via StockAnalysis; PKR million except shares/BVPS
A6: Accounts Receivable | B6: 36.355 | C6: 59.904 | D6: 67.225 | E6: 61.738 | F6: 64.539 | G6: S&P Global Market Intelligence via StockAnalysis; PKR million except shares/BVPS
A7: Other Receivables | B7: 19.293 | C7: 14.974 | D7: 17.894 | E7: 15.227 | F7: 24.728 | G7: S&P Global Market Intelligence via StockAnalysis; PKR million except shares/BVPS
A8: Inventory | B8: 85.679 | C8: 71.269 | D8: 92.884 | E8: 91.275 | F8: 88.774 | G8: S&P Global Market Intelligence via StockAnalysis; PKR million except shares/BVPS
A9: Total Current Assets | B9: 175.726 | C9: 238.776 | D9: 274.631 | E9: 320.554 | F9: 371.348 | G9: S&P Global Market Intelligence via StockAnalysis; PKR million except shares/BVPS
A10: Property, Plant & Equipment | B10: 276.193 | C10: 294.956 | D10: 298.754 | E10: 305.709 | F10: 305.143 | G10: S&P Global Market Intelligence via StockAnalysis; PKR million except shares/BVPS
A11: Long-Term Investments | B11: 36.545 | C11: 67.118 | D11: 78.083 | E11: 92.218 | F11: 104.252 | G11: S&P Global Market Intelligence via StockAnalysis; PKR million except shares/BVPS
A12: Goodwill | B12: 3.029 | C12: 2.34 | D12: 2.34 | E12: 2.34 | F12: 0 | G12: S&P Global Market Intelligence via StockAnalysis; PKR million except shares/BVPS
A13: Other Intangible Assets | B13: 11.573 | C13: 4.343 | D13: 4.285 | E13: 5.772 | F13: 8.135 | G13: S&P Global Market Intelligence via StockAnalysis; PKR million except shares/BVPS
... A27: Book Value Per Share (PKR) | B27: 105.68 | C27: 145.9 | D27: 186.78 | E27: 237.07 | F27: 292.51 | G27: S&P Global Market Intelligence via StockAnalysis; PKR million except shares/BVPS

Sheet Cash Flow
A1: Metric | B1: FY2022 | C1: FY2023 | D1: FY2024 | E1: FY2025 | F1: FY2026 | G1: Source
A2: Operating Cash Flow | B2: -29.484 | C2: 57.676 | D2: 45.207 | E2: 96.742 | F2: 54.831 | G2: S&P Global Market Intelligence via StockAnalysis; PKR million
A3: Capital Expenditures | B3: -55.671 | C3: -24.305 | D3: -24.812 | E3: -20.981 | F3: -21.377 | G3: S&P Global Market Intelligence via StockAnalysis; PKR million
A4: Free Cash Flow | B4: -85.154 | C4: 33.371 | D4: 20.395 | E4: 75.761 | F4: 33.453 | G4: S&P Global Market Intelligence via StockAnalysis; PKR million

Sheet Market Snapshot
A1: Metric | B1: Value | C1: Date/Period | D1: Source
A2: Current Share Price (PKR) | B2: 436.66 | C2: 20-Aug-2026 close | D2: S&P Global Market Intelligence via StockAnalysis
A3: Shares Outstanding (million) | B3: 1465 | C3: FY2026 | D3: PSX / Lucky Cement
A4: Market Capitalization (PKR bn) | C4: 20-Aug-2026 | D4: Calculate in Excel = price × shares
A5: Fiscal Year End | B5: June 30 | C5: FY2026 | D5: PSX
A6: Ticker | B6: LUCK | C6: Current | D6: PSX
A7: Exchange | B7: Pakistan Stock Exchange | C7: Current | D7: PSX
A8: Sector | B8: Materials | C8: Current | D8: PSX / market data
A9: Stock Split | B9: 5-for-1 | C9: 23-Apr-2025 | D9: S&P Global Market Intelligence / company disclosures
A10: FY2026 Dividend Per Share (PKR) | B10: 5 | C10: FY2026 | D10: StockAnalysis / company results
A11: FY2026 EPS (PKR) | B11: 60.78 | C11: FY2026 | D11: Lucky Cement FY2026 results

Sheet Stock Price - Recent
A1: Date | B1: Open | C1: High | D1: Low | E1: Close | F1: Volume | G1: Source
A2: 2026-08-19 | B2: 439.3 | C2: 443.21 | D2: 435 | E2: 437.2 | F2: 981329 | G2: S&P Global Market Intelligence via StockAnalysis
A3: 2026-08-18 | B3: 443.4 | C3: 444 | D3: 438 | E3: 439.3 | F3: 1250095 | G3: S&P Global Market Intelligence via StockAnalysis
A4: 2026-08-17 | B4: 448.01 | C4: 449.4 | D4: 442 | E4: 443.37 | F4: 753981 | G4: S&P Global Market Intelligence via StockAnalysis
A5: 2026-08-13 | B5: 447.88 | C5: 450 | D5: 445 | E5: 446.61 | F5: 696125 | G5: S&P Global Market Intelligence via StockAnalysis
A6: 2026-08-12 | B6: 445.7 | C6: 450.12 | D6: 443 | E6: 446.47 | F6: 1099611 | G6: S&P Global Market Intelligence via StockAnalysis
A7: 2026-08-11 | B7: 454.3 | C7: 454.3 | D7: 443.99 | E7: 445.11 | F7: 1441981 | G7: S&P Global Market Intelligence via StockAnalysis
A8: 2026-08-10 | B8: 462.8 | C8: 462.8 | D8: 452.99 | E8: 454.36 | F8: 2057991 | G8: S&P Global Market Intelligence via StockAnalysis
A9: 2026-08-07 | B9: 457.5 | C9: 462 | D9: 453 | E9: 458.75 | F9: 1949072 | G9: S&P Global Market Intelligence via StockAnalysis
A10: 2026-08-06 | B10: 453.91 | C10: 460.5 | D10: 453.91 | E10: 458.63 | F10: 1931851 | G10: S&P Global Market Intelligence via StockAnalysis
A11: 2026-08-05 | B11: 454.39 | C11: 456.78 | D11: 450.12 | E11: 451.97 | F11: 2675868 | G11: S&P Global Market Intelligence via StockAnalysis
A12: 2026-08-04 | B12: 450 | C12: 451.99 | D12: 442.5 | E12: 443.4 | F12: 1031670 | G12: S&P Global Market Intelligence via StockAnalysis
A13: 2026-08-03 | B13: 450 | C13: 454.99 | D13: 446.01 | E13: 449.08 | F13: 1884947 | G13: S&P Global Market Intelligence via StockAnalysis
... A51: 2026-06-08 | B51: 426 | C51: 429.9 | D51: 423.5 | E51: 426.49 | F51: 1162090 | G51: S&P Global Market Intelligence via StockAnalysis

Sheet Segment Revenue
A1: Segment | B1: FY2022 | C1: FY2023 | D1: FY2024 | E1: FY2025 | F1: Source
A2: Cement | B2: 81.126 | C2: 95.843 | D2: 115.341 | E2: 124.565 | F2: StockAnalysis / S&P Global Market Intelligence
A3: Polyester | B3: 36.678 | C3: 40.452 | D3: 40.285 | E3: 39.731 | F3: StockAnalysis / S&P Global Market Intelligence
A4: Soda Ash | B4: 25.064 | C4: 41.417 | D4: 47.565 | E4: 39.764 | F4: StockAnalysis / S&P Global Market Intelligence
A5: Pharma | B5: 8.886 | C5: 9.159 | D5: 12.212 | E5: 21.043 | F5: StockAnalysis / S&P Global Market Intelligence
A6: Life Sciences & Chemicals | B6: 14.726 | C6: 18.559 | D6: 20.494 | E6: 19.521 | F6: StockAnalysis / S&P Global Market Intelligence
A7: Automobiles & Mobile Phones Assembling | B7: 124.61 | C7: 82.238 | D7: 85.134 | E7: 136.14 | F7: StockAnalysis / S&P Global Market Intelligence
A8: Power Generation | B8: 33.786 | C8: 98.28 | D8: 90.954 | E8: 70.08 | F8: StockAnalysis / S&P Global Market Intelligence
A9: Others | B9: 3.808 | C9: 1.802 | D9: 1.536 | E9: 1.412 | F9: StockAnalysis / S&P Global Market Intelligence
A10: Inter-segment eliminations | B10: -3.284 | C10: -2.625 | D10: -2.527 | E10: -2.626 | F10: StockAnalysis / S&P Global Market Intelligence

Sheet DCF Inputs - Raw
A1: Input | B1: Value | C1: Unit | D1: Status | E1: Source/Note
A2: Current share price | B2: 436.66 | C2: PKR/share | D2: Observed | E2: 20-Aug-2026 close
A3: Shares outstanding | B3: 1465 | C3: million | D3: Observed | E3: PSX / FY2026
A4: FY2026 Net Revenue | B4: 516358.81 | C4: PKR million | D4: Historical | E4: FY2026 results
A5: FY2026 Profit After Tax | B5: 96456.241 | C5: PKR million | D5: Historical | E5: FY2026 results
A6: FY2026 Operating Cash Flow | B6: 54831 | C6: PKR million | D6: Historical | E6: S&P Global / StockAnalysis
A7: FY2026 CapEx | B7: -21377 | C7: PKR million | D7: Historical | E7: S&P Global / StockAnalysis
A8: FY2026 Free Cash Flow | B8: 33453 | C8: PKR million | D8: Historical | E8: S&P Global / StockAnalysis
A9: FY2026 Total Debt | B9: 184974 | C9: PKR million | D9: Historical | E9: S&P Global / StockAnalysis
A10: FY2026 Cash & Investments | B10: 181961 | C10: PKR million | D10: Historical | E10: S&P Global / StockAnalysis
A11: Tax rate | B11: =19734.002/116190.243 -> 0.16984216 | C11: % | D11: To be calculated | E11: Use project methodology; do not assume yet
A12: Risk-free rate | B12: 0.1209 | C12: % | D12: To be researched | E12: Use current Pakistan government benchmark
A13: Beta | B13: 0.57 | C13: x | D13: To be researched | E13: Use consistent market-data source
A14: Equity risk premium | B14: 0.1394 | C14: % | D14: To be researched | E14: Use chosen methodology
A15: Cost of debt | B15: 0.1021 | C15: % | D15: To be calculated/researched | E15: Use company financial data
A16: WACC | B16: =(71.93%*20.04%)+(28.07%*10.21%*(1-16.98%)) -> 0.16794081 | C16: % | D16: To be calculated | E16: Excel model
A17: DCF Forecast | B17: FY2027 | C17: FY2028 | D17: FY2029 | E17: FY2030 | F17: FY2031
A18: Revenue Growth | B18: 0.12 | C18: 0.115 | D18: 0.11 | E18: 0.105 | F18: 0.1
A19: Net Revenue | B19: =516.359*(1+B18) -> 578.32208 | C19: =B19*(1+C18) -> 644.82912 | D19: =C19*(1+D18) -> 715.76032 | E19: =D19*(1+E18) -> 790.91516 | F19: =E19*(1+F18) -> 870.00667
A20: EBITDA Margin | B20: 0.2 | C20: 0.2025 | D20: 0.205 | E20: 0.2075 | F20: 0.21
A21: EBITDA | B21: =B19*B20 -> 115.66442 | C21: =C19*C20 -> 130.5779 | D21: =D19*D20 -> 146.73087 | E21: =E19*E20 -> 164.11489 | F21: =F19*F20 -> 182.7014
A22: D&A(% OF REVENUE) | B22: 0.05 | C22: 0.05 | D22: 0.05 | E22: 0.05 | F22: 0.05
A23: D&A | B23: =B19*B22 -> 28.916104 | C23: =C19*C22 -> 32.241456 | D23: =D19*D22 -> 35.788016 | E23: =E19*E22 -> 39.545758 | F23: =F19*F22 -> 43.500334
A24: EBIT | B24: =B21-B23 -> 86.748312 | C24: =C21-C23 -> 98.336441 | D24: =D21-D23 -> 110.94285 | E24: =E21-E23 -> 124.56914 | F24: =F21-F23 -> 139.20107
A25: Tax Rate | B25: 0.29 | C25: 0.29 | D25: 0.29 | E25: 0.29 | F25: 0.29
A26: Tax Expense | B26: =B24*B25 -> 25.15701 | C26: =C24*C25 -> 28.517568 | D26: =D24*D25 -> 32.173426 | E26: =E24*E25 -> 36.12505 | F26: =F24*F25 -> 40.36831
A27: NOPAT | B27: =B24-B26 -> 61.591302 | C27: =C24-C26 -> 69.818873 | D27: =D24-D26 -> 78.769423 | E27: =E24-E26 -> 88.444087 | F27: =F24-F26 -> 98.832758
A28: CapEx (% of Revenue) | B28: 0.06 | C28: 0.06 | D28: 0.06 | E28: 0.06 | F28: 0.06
A29: Change in NWC (% of Revenue) | B29: 0.01 | C29: 0.01 | D29: 0.01 | E29: 0.01 | F29: 0.01
A30: CapEx | B30: =B19*B28 -> 34.699325 | C30: =C19*C28 -> 38.689747 | D30: =D19*D28 -> 42.945619 | E30: =E19*E28 -> 47.454909 | F30: =F19*F28 -> 52.2004
A31: Change in NWC | B31: =B19*B29 -> 5.7832208 | C31: =C19*C29 -> 6.4482912 | D31: =D19*D29 -> 7.1576032 | E31: =E19*E29 -> 7.9091516 | F31: =F19*F29 -> 8.7000667
A32: FCFF | B32: =B27+B23-B30-B31 -> 50.02486 | C32: =C27+C23-C30-C31 -> 56.92229 | D32: =D27+D23-D30-D31 -> 64.454217 | E32: =E27+E23-E30-E31 -> 72.625784 | F32: =F27+F23-F30-F31 -> 81.432624
A33: Year | B33: 1 | C33: 2 | D33: 3 | E33: 4 | F33: 5
A34: Discount Factor | B34: =1/(1+$B$16)^B33 -> 0.85620777 | C34: =1/(1+$B$16)^C33 -> 0.73309175 | D34: =1/(1+$B$16)^D33 -> 0.62767885 | E34: =1/(1+$B$16)^E33 -> 0.53742351 | F34: =1/(1+$B$16)^F33 -> 0.46014619
A35: PV of FCFF | B35: =B32*B34 -> 42.831674 | C35: =C32*C34 -> 41.729261 | D35: =D32*D34 -> 40.456549 | E35: =E32*E34 -> 39.030804 | F35: =F32*F34 -> 37.470912
A36: Terminal Growth Rate | B36: 0.03
A37: Terminal Value | F37: =F32*(1+B36)/($B$16-B36) -> 608.05502
A38: PV of Terminal Value | F38: =F37*F34 -> 279.7942
A39: Enterprise Value | B39: =SUM(B35:F35)+F38 -> 481.3134
A40: Net Debt | B40: 176.114
...

Sheet Financial analysis
A1: Lucky Cement -Financial Analysis
A2: FY2022-FY2026
A4: Metric | B4: FY2022 | C4: FY2023 | D4: FY2024 | E4: FY2025 | F4: FY2026
A5: Revenue Growth | B5: N/A | C5: ='Income Statement'!C5/'Income Statement'!B5-1 -> 0.16189807 | D5: ='Income Statement'!D5/'Income Statement'!C5-1 -> 0.067172942 | E5: ='Income Statement'!E5/'Income Statement'!D5-1 -> 0.10478172 | F5: ='Income Statement'!F5/'Income Statement'!E5-1 -> 0.137204
A6: Gross Profit Margin | B6: ='Income Statement'!B7/'Income Statement'!B5 -> 0.19058436 | C6: ='Income Statement'!C7/'Income Statement'!C5 -> 0.24312614 | D6: ='Income Statement'!D7/'Income Statement'!D5 -> 0.30053136 | E6: ='Income Statement'!E7/'Income Statement'!E5 -> 0.28006855 | F6: ='Income Statement'!F7/'Income Statement'!F5 -> 0.25429028
A7: Operating Profit Margin | B7: =('Income Statement'!B7-'Income Statement'!B8-'Income Statement'!B9)/'Income Statement'!B5 -> 0.13753022 | C7: =('Income Statement'!C7-'Income Statement'!C8-'Income Statement'!C9)/'Income Statement'!C5 -> 0.19810506 | D7: =('Income Statement'!D7-'Income Statement'!D8-'Income Statement'!D9)/'Income Statement'!D5 -> 0.24350257 | E7: =('Income Statement'!E7-'Income Statement'!E8-'Income Statement'!E9)/'Income Statement'!E5 -> 0.22542062 | F7: =('Income Statement'!F7-'Income Statement'!F8-'Income Statement'!F9)/'Income Statement'!F5 -> 0.20485752
A8: Net Profit Margin | B8: ='Income Statement'!B17/'Income Statement'!B5 -> 0.10988487 | C8: ='Income Statement'!C17/'Income Statement'!C5 -> 0.12660342 | D8: ='Income Statement'!D17/'Income Statement'!D5 -> 0.17600388 | E8: ='Income Statement'!E17/'Income Statement'!E5 -> 0.18609519 | F8: ='Income Statement'!F17/'Income Statement'!F5 -> 0.1868008
A9: ROE | B9: ='Income Statement'!B17/'Balance Sheet'!B23 -> 0.18233397 | C9: ='Income Statement'!C17/'Balance Sheet'!C23 -> 0.18681362 | D9: ='Income Statement'!D17/'Balance Sheet'!D23 -> 0.23287034 | E9: ='Income Statement'!E17/'Balance Sheet'!E23 -> 0.21775631 | F9: ='Income Statement'!F17/'Balance Sheet'!F23 -> 0.20353497
A10: ROA | B10: ='Income Statement'!B17/'Balance Sheet'!B14 -> 0.07231211 | C10: ='Income Statement'!C17/'Balance Sheet'!C14 -> 0.08014703 | D10: ='Income Statement'!D17/'Balance Sheet'!D14 -> 0.10965729 | E10: ='Income Statement'!E17/'Balance Sheet'!E14 -> 0.11585245 | F10: ='Income Statement'!F17/'Balance Sheet'!F14 -> 0.12149564
A11: Debt-to-Equity | B11: ='Balance Sheet'!B24/'Balance Sheet'!B23 -> 0.95762372 | C11: ='Balance Sheet'!C24/'Balance Sheet'!C23 -> 0.81234028 | D11: ='Balance Sheet'!D24/'Balance Sheet'!D23 -> 0.66255461 | E11: ='Balance Sheet'!E24/'Balance Sheet'!E23 -> 0.47928956 | F11: ='Balance Sheet'!F24/'Balance Sheet'!F23 -> 0.39031873
A12: Current Ratio | B12: ='Balance Sheet'!B9/'Balance Sheet'!B18 -> 1.176818 | C12: ='Balance Sheet'!C9/'Balance Sheet'!C18 -> 1.3607486 | D12: ='Balance Sheet'!D9/'Balance Sheet'!D18 -> 1.4942571 | E12: ='Balance Sheet'!E9/'Balance Sheet'!E18 -> 1.8031546 | F12: ='Balance Sheet'!F9/'Balance Sheet'!F18 -> 2.1847984
A13: EPS Growth | B13: N/A | C13: =('Income Statement'!C20/'Income Statement'!B20)-1 -> 0.67708333 | D13: =('Income Statement'!D20/'Income Statement'!C20)-1 -> 0.4416476 | E13: =('Income Statement'!E20/'Income Statement'!D20)-1 -> 0.19115646 | F13: =('Income Statement'!F20/'Income Statement'!E20)-1 -> 0.15705311
A14: Free Cash Flow | B14: ='Cash Flow'!B2+'Cash Flow'!B3 -> -85.155 | C14: ='Cash Flow'!C2+'Cash Flow'!C3 -> 33.371 | D14: ='Cash Flow'!D2+'Cash Flow'!D3 -> 20.395 | E14: ='Cash Flow'!E2+'Cash Flow'!E3 -> 75.761 | F14: ='Cash Flow'!F2+'Cash Flow'!F3 -> 33.454

Sheet key Assumptions & Conclusion
A1: Key Assumptions & Conclusion
A3: Key Assumptions
A4: Assumption | B4: Value
A5: WACC | B5: 0.16
A6: Terminal Growth Rate | B6: 0.03
A7: Forecast Period | B7: 2026-2030
A8: Intrinsic Value Per Share | B8: 208.33
A9: Current Market Price | B9: 436.66
A10: Upside / (Downside) | B10: -0.5229
A13: Conclusion
A14: Based on the DCF model,Lucky Cement's intrinsic value per share is Rs.208.33
A15: compared with the current market price of Rs.436.66,implying a downside of
A16: 52.29%. Under the base-case assumptions, the stock appears overvalued.

Sheet Dashboard
A1: Lucky Cement_Financial Analysis Dashboard
A2: FY2022_FY2026
A4: REVENUE | C4: NET PROFIT MARGIN | E4: EPS | G4: INTRINSIC VALUE
A5: ='Income Statement'!F5 -> 516.35881 | C5: ='Financial analysis'!F8 -> 0.1868008 | E5: ='Income Statement'!F18 -> 60.78 | G5: ='DCF Inputs - Raw'!B43 -> 208.32723
A8: Company OVERVIEW
A9: Company Name | B9: Lucky Cement Limited
A10: Industry | B10: Cement
A11: Fiscal Year | B11: FY2026
A12: Stock Symbol | B12: LUCK
A14: Financial Performance
J15: YEAR | K15: REVENUE | L15: PAT
J16: FY2022 | K16: 331.462 | L16: 36.423
J17: FY2023 | K17: 385.125 | L17: 48.758
J18: FY2024 | K18: 410.995 | L18: 72.337
J19: FY2025 | K19: 454.06 | L19: 84.498
J20: FY2026 | K20: 516.359 | L20: 96.456
J22: YEAR | K22: EPS
J23: FY2022 | K23: 91.22
J24: FY2023 | K24: 30.59
J25: FY2024 | K25: 44.1
J26: FY2025 | K26: 52.53
J27: FY2026 | K27: 60.78
A31: DCF VALUATION
A33: Enterprise value | C33: Equity Value | E33: Intrinsic Value | G33: Market Price | J33: Valuation | K33: PKR/Share
A34: PKR 481.3 BN | C34: PKR 305.2 BN | E34: PKR 208.33 | G34: PKR 436.66 | J34: Intrinsic Value | K34: 208.33
J35: Market Price | K35: 436.66
D39: DCF KEY ASSUMPTIONS
B42: 16
D43: WACC | E43: 0.1679
D44: Terminal Growth | E44: 0.03
D45: Upside/ Downside | E45: -0.5229
D47: DCF Conclusion BOX
D48: DCF indicates the stock is overvalued at the
D49: current market price.
A54: SENSITIVITY ANALYSIS
A56: WACC / Growth | B56: 0.02 | C56: 0.025 | D56: 0.03 | E56: 0.035 | F56: 0.04 | H56: VALUATION RANGE
A57: 0.14 | B57: 272.94 | C57: 284.87 | D57: 297.88 | E57: 312.12 | F57: 327.79
A58: 0.15 | B58: 240.6 | C58: 250.38 | D58: 260.97 | E58: 272.49 | F58: 327.79 | H58: Lowest Intrinsic Value | J58: 168.17
A59: 0.16 | B59: 212.94 | C59: 221.07 | D59: 229.81 | E59: 239.26 | F59: 249.49 | H59: Highest Intrinsic Value | J59: 327.79
A60: 0.17 | B60: 189.03 | C60: 195.85 | D60: 203.16 | E60: 211.01 | F60: 219.46
...

Sheet Case Study
A1: LUCKY CEMENT_CASE STUDY
A4: PROBLEM
A5: Assess Lucky Cement’s financial performance and determine whether its current market price
A6: is justified by its intrinsic value.
A10: METHOD
A11: Analyzed FY2022_FY2026 financial performance,profitability and EPS trends,
A12: followed by DCF valuation and sensitivity analysis.
A16: INSIGHT
A17: Financial performance remains strong,but the DCF estimates an intrinsic value of PKR 208.33
A18: versus a market price of approximately PKR 436.66, indicating significant overvaluation.
A22: RECOMMENDATION
A23: Hold / Wait for a Better Entry.Consider investing at a more attractive valuation or if
A24: future fundamentals support a higher intrinsic value.
